log/output_300_2021_GRU_gpu2.log
wandb: Currently logged in as: pqy000 (pqythu). Use `wandb login --relogin` to force relogin
GPU device ID: 2
newdata/300_2021.npy
0
2024-09-07 12:05:12.201556: I tensorflow/core/platform/cpu_feature_guard.cc:193] This TensorFlow binary is optimized with oneAPI Deep Neural Network Library (oneDNN) to use the following CPU instructions in performance-critical operations:  AVX2 FMA
To enable them in other operations, rebuild TensorFlow with the appropriate compiler flags.
2024-09-07 12:05:13.174451: W tensorflow/compiler/xla/stream_executor/platform/default/dso_loader.cc:64] Could not load dynamic library 'libnvinfer.so.7'; dlerror: libnvinfer.so.7: cannot open shared object file: No such file or directory; LD_LIBRARY_PATH: /opt/cudnn/lib64:/usr/local/cuda/lib64
2024-09-07 12:05:13.174546: W tensorflow/compiler/xla/stream_executor/platform/default/dso_loader.cc:64] Could not load dynamic library 'libnvinfer_plugin.so.7'; dlerror: libnvinfer_plugin.so.7: cannot open shared object file: No such file or directory; LD_LIBRARY_PATH: /opt/cudnn/lib64:/usr/local/cuda/lib64
2024-09-07 12:05:13.174559: W tensorflow/compiler/tf2tensorrt/utils/py_utils.cc:38] TF-TRT Warning: Cannot dlopen some TensorRT libraries. If you would like to use Nvidia GPU with TensorRT, please make sure the missing libraries mentioned above are installed properly.
wandb: wandb version 0.17.9 is available!  To upgrade, please run:
wandb:  $ pip install wandb --upgrade
wandb: Tracking run with wandb version 0.12.17
wandb: Run data is saved locally in /home/qingyi/GPU20/DeepLOB/wandb/run-20240907_120506-d8pfxkbr
wandb: Run `wandb offline` to turn off syncing.
wandb: Syncing run GRU
wandb: ⭐️ View project at https://wandb.ai/pqythu/futures300
wandb: 🚀 View run at https://wandb.ai/pqythu/futures300/runs/d8pfxkbr
Model(
  (rnn): GRU(10, 64, batch_first=True)
  (fc): Linear(in_features=64, out_features=5, bias=True)
)
number of parameters: 14917
Training start
epoch  1 | time used:  2.19s | train_loss 1.467 | valid loss 1.555 | valid acc 0.287 | mae 2.200 | mse 7.640 | rmse 2.76 | r2 -1.73 | sharp 0.00
epoch  2 | time used:  0.08s | train_loss 1.451 | valid loss 1.555 | valid acc 0.287 | mae 2.200 | mse 7.640 | rmse 2.76 | r2 -1.73 | sharp 0.00
epoch  3 | time used:  0.08s | train_loss 1.460 | valid loss 1.441 | valid acc 0.287 | mae 2.200 | mse 7.640 | rmse 2.76 | r2 -1.73 | sharp 0.00
epoch  4 | time used:  0.08s | train_loss 1.451 | valid loss 1.555 | valid acc 0.287 | mae 2.200 | mse 7.640 | rmse 2.76 | r2 -1.73 | sharp 0.00
epoch  5 | time used:  0.10s | train_loss 1.472 | valid loss 1.420 | valid acc 0.388 | mae 1.800 | mse 6.040 | rmse 2.46 | r2 -1.16 | sharp 0.75
epoch  6 | time used:  0.10s | train_loss 1.509 | valid loss 1.422 | valid acc 0.388 | mae 1.800 | mse 6.040 | rmse 2.46 | r2 -1.16 | sharp 0.75
epoch  7 | time used:  0.10s | train_loss 1.512 | valid loss 1.421 | valid acc 0.388 | mae 1.800 | mse 6.040 | rmse 2.46 | r2 -1.16 | sharp 0.75
epoch  8 | time used:  0.11s | train_loss 1.476 | valid loss 1.555 | valid acc 0.287 | mae 2.200 | mse 7.640 | rmse 2.76 | r2 -1.73 | sharp 0.00
epoch  9 | time used:  0.09s | train_loss 1.453 | valid loss 1.555 | valid acc 0.287 | mae 2.200 | mse 7.640 | rmse 2.76 | r2 -1.73 | sharp 0.00
epoch 10 | time used:  0.09s | train_loss 1.455 | valid loss 1.552 | valid acc 0.287 | mae 2.200 | mse 7.640 | rmse 2.76 | r2 -1.73 | sharp 0.00
saving the model to ./save/2021_300/GRU/checkpoint10.pt
epoch 11 | time used:  0.09s | train_loss 1.452 | valid loss 1.555 | valid acc 0.287 | mae 2.200 | mse 7.640 | rmse 2.76 | r2 -1.73 | sharp 0.00
epoch 12 | time used:  0.09s | train_loss 1.456 | valid loss 1.555 | valid acc 0.287 | mae 2.200 | mse 7.640 | rmse 2.76 | r2 -1.73 | sharp 0.00
epoch 13 | time used:  0.09s | train_loss 1.470 | valid loss 1.420 | valid acc 0.388 | mae 1.800 | mse 6.040 | rmse 2.46 | r2 -1.16 | sharp 0.75
epoch 14 | time used:  0.10s | train_loss 1.504 | valid loss 1.420 | valid acc 0.388 | mae 1.800 | mse 6.040 | rmse 2.46 | r2 -1.16 | sharp 0.75
epoch 15 | time used:  0.10s | train_loss 1.446 | valid loss 1.555 | valid acc 0.287 | mae 2.200 | mse 7.640 | rmse 2.76 | r2 -1.73 | sharp 0.00
epoch 16 | time used:  0.08s | train_loss 1.455 | valid loss 1.555 | valid acc 0.287 | mae 2.200 | mse 7.640 | rmse 2.76 | r2 -1.73 | sharp 0.00
epoch 17 | time used:  0.10s | train_loss 1.473 | valid loss 1.420 | valid acc 0.388 | mae 1.800 | mse 6.040 | rmse 2.46 | r2 -1.16 | sharp 0.75
epoch 18 | time used:  0.10s | train_loss 1.511 | valid loss 1.420 | valid acc 0.388 | mae 1.800 | mse 6.040 | rmse 2.46 | r2 -1.16 | sharp 0.75
epoch 19 | time used:  0.09s | train_loss 1.506 | valid loss 1.420 | valid acc 0.388 | mae 1.800 | mse 6.040 | rmse 2.46 | r2 -1.16 | sharp 0.75
epoch 20 | time used:  0.10s | train_loss 1.511 | valid loss 1.420 | valid acc 0.388 | mae 1.800 | mse 6.040 | rmse 2.46 | r2 -1.16 | sharp 0.75
saving the model to ./save/2021_300/GRU/checkpoint20.pt
epoch 21 | time used:  0.09s | train_loss 1.505 | valid loss 1.420 | valid acc 0.388 | mae 1.800 | mse 6.040 | rmse 2.46 | r2 -1.16 | sharp 0.75
epoch 22 | time used:  0.09s | train_loss 1.507 | valid loss 1.420 | valid acc 0.388 | mae 1.800 | mse 6.040 | rmse 2.46 | r2 -1.16 | sharp 0.75
epoch 23 | time used:  0.07s | train_loss 1.506 | valid loss 1.420 | valid acc 0.388 | mae 1.800 | mse 6.040 | rmse 2.46 | r2 -1.16 | sharp 0.75
epoch 24 | time used:  0.06s | train_loss 1.508 | valid loss 1.424 | valid acc 0.388 | mae 1.800 | mse 6.040 | rmse 2.46 | r2 -1.16 | sharp 0.75
epoch 25 | time used:  0.06s | train_loss 1.507 | valid loss 1.423 | valid acc 0.388 | mae 1.800 | mse 6.040 | rmse 2.46 | r2 -1.16 | sharp 0.75
epoch 26 | time used:  0.06s | train_loss 1.508 | valid loss 1.420 | valid acc 0.388 | mae 1.800 | mse 6.040 | rmse 2.46 | r2 -1.16 | sharp 0.75
epoch 27 | time used:  0.06s | train_loss 1.505 | valid loss 1.420 | valid acc 0.388 | mae 1.800 | mse 6.040 | rmse 2.46 | r2 -1.16 | sharp 0.75
epoch 28 | time used:  0.09s | train_loss 1.510 | valid loss 1.420 | valid acc 0.388 | mae 1.800 | mse 6.040 | rmse 2.46 | r2 -1.16 | sharp 0.75
epoch 29 | time used:  0.10s | train_loss 1.504 | valid loss 1.420 | valid acc 0.388 | mae 1.800 | mse 6.040 | rmse 2.46 | r2 -1.16 | sharp 0.75
epoch 30 | time used:  0.10s | train_loss 1.473 | valid loss 1.555 | valid acc 0.287 | mae 2.200 | mse 7.640 | rmse 2.76 | r2 -1.73 | sharp 0.00
saving the model to ./save/2021_300/GRU/checkpoint30.pt
epoch 31 | time used:  0.10s | train_loss 1.458 | valid loss 1.555 | valid acc 0.287 | mae 2.200 | mse 7.640 | rmse 2.76 | r2 -1.73 | sharp 0.00
epoch 32 | time used:  0.09s | train_loss 1.449 | valid loss 1.555 | valid acc 0.287 | mae 2.200 | mse 7.640 | rmse 2.76 | r2 -1.73 | sharp 0.00
epoch 33 | time used:  0.13s | train_loss 1.453 | valid loss 1.555 | valid acc 0.287 | mae 2.200 | mse 7.640 | rmse 2.76 | r2 -1.73 | sharp 0.00
epoch 34 | time used:  0.07s | train_loss 1.450 | valid loss 1.555 | valid acc 0.287 | mae 2.200 | mse 7.640 | rmse 2.76 | r2 -1.73 | sharp 0.00
epoch 35 | time used:  0.08s | train_loss 1.498 | valid loss 1.420 | valid acc 0.388 | mae 1.800 | mse 6.040 | rmse 2.46 | r2 -1.16 | sharp 0.75
epoch 36 | time used:  0.09s | train_loss 1.503 | valid loss 1.420 | valid acc 0.388 | mae 1.800 | mse 6.040 | rmse 2.46 | r2 -1.16 | sharp 0.75
epoch 37 | time used:  0.09s | train_loss 1.502 | valid loss 1.420 | valid acc 0.388 | mae 1.800 | mse 6.040 | rmse 2.46 | r2 -1.16 | sharp 0.75
epoch 38 | time used:  0.09s | train_loss 1.508 | valid loss 1.420 | valid acc 0.388 | mae 1.800 | mse 6.040 | rmse 2.46 | r2 -1.16 | sharp 0.75
epoch 39 | time used:  0.09s | train_loss 1.450 | valid loss 1.555 | valid acc 0.287 | mae 2.200 | mse 7.640 | rmse 2.76 | r2 -1.73 | sharp 0.00
epoch 40 | time used:  0.10s | train_loss 1.450 | valid loss 1.555 | valid acc 0.287 | mae 2.200 | mse 7.640 | rmse 2.76 | r2 -1.73 | sharp 0.00
saving the model to ./save/2021_300/GRU/checkpoint40.pt
