log/output_300_2021_GRU_gpu3.log
wandb: Currently logged in as: pqy000 (pqythu). Use `wandb login --relogin` to force relogin
GPU device ID: 3
newdata/300_2021.npy
0
2024-09-07 16:05:40.559164: I tensorflow/core/platform/cpu_feature_guard.cc:193] This TensorFlow binary is optimized with oneAPI Deep Neural Network Library (oneDNN) to use the following CPU instructions in performance-critical operations:  AVX2 FMA
To enable them in other operations, rebuild TensorFlow with the appropriate compiler flags.
wandb: wandb version 0.17.9 is available!  To upgrade, please run:
wandb:  $ pip install wandb --upgrade
wandb: Tracking run with wandb version 0.12.17
wandb: Run data is saved locally in /home/qingyi/GPU20/DeepLOB/wandb/run-20240907_160533-2kmm9bly
wandb: Run `wandb offline` to turn off syncing.
wandb: Syncing run GRU
wandb: ⭐️ View project at https://wandb.ai/pqythu/futures300
wandb: 🚀 View run at https://wandb.ai/pqythu/futures300/runs/2kmm9bly
2024-09-07 16:05:41.619472: W tensorflow/compiler/xla/stream_executor/platform/default/dso_loader.cc:64] Could not load dynamic library 'libnvinfer.so.7'; dlerror: libnvinfer.so.7: cannot open shared object file: No such file or directory; LD_LIBRARY_PATH: /opt/cudnn/lib64:/usr/local/cuda/lib64
2024-09-07 16:05:41.619593: W tensorflow/compiler/xla/stream_executor/platform/default/dso_loader.cc:64] Could not load dynamic library 'libnvinfer_plugin.so.7'; dlerror: libnvinfer_plugin.so.7: cannot open shared object file: No such file or directory; LD_LIBRARY_PATH: /opt/cudnn/lib64:/usr/local/cuda/lib64
2024-09-07 16:05:41.619608: W tensorflow/compiler/tf2tensorrt/utils/py_utils.cc:38] TF-TRT Warning: Cannot dlopen some TensorRT libraries. If you would like to use Nvidia GPU with TensorRT, please make sure the missing libraries mentioned above are installed properly.
Model(
  (rnn): LSTM(10, 64, batch_first=True)
  (fc): Linear(in_features=64, out_features=5, bias=True)
)
number of parameters: 19781
Training start
epoch  1 | time used:  1.02s | train_loss 1.478 | valid loss 1.392 | valid acc 0.380 | mae 1.645 | mse 5.115 | rmse 2.26 | r2 -1.12 | sharp 0.36
epoch  2 | time used:  0.09s | train_loss 1.483 | valid loss 1.392 | valid acc 0.380 | mae 1.645 | mse 5.115 | rmse 2.26 | r2 -1.12 | sharp 0.36
epoch  3 | time used:  0.06s | train_loss 1.479 | valid loss 1.393 | valid acc 0.380 | mae 1.645 | mse 5.115 | rmse 2.26 | r2 -1.12 | sharp 0.36
epoch  4 | time used:  0.05s | train_loss 1.526 | valid loss 1.622 | valid acc 0.205 | mae 2.355 | mse 7.955 | rmse 2.82 | r2 -2.30 | sharp 0.00
epoch  5 | time used:  0.04s | train_loss 1.497 | valid loss 1.393 | valid acc 0.380 | mae 1.645 | mse 5.115 | rmse 2.26 | r2 -1.12 | sharp 0.36
epoch  6 | time used:  0.06s | train_loss 1.487 | valid loss 1.401 | valid acc 0.380 | mae 1.645 | mse 5.115 | rmse 2.26 | r2 -1.12 | sharp 0.36
epoch  7 | time used:  0.14s | train_loss 1.487 | valid loss 1.393 | valid acc 0.380 | mae 1.645 | mse 5.115 | rmse 2.26 | r2 -1.12 | sharp 0.36
epoch  8 | time used:  0.12s | train_loss 1.481 | valid loss 1.393 | valid acc 0.380 | mae 1.645 | mse 5.115 | rmse 2.26 | r2 -1.12 | sharp 0.36
epoch  9 | time used:  0.05s | train_loss 1.454 | valid loss 1.393 | valid acc 0.380 | mae 1.645 | mse 5.115 | rmse 2.26 | r2 -1.12 | sharp 0.36
epoch 10 | time used:  0.04s | train_loss 1.463 | valid loss 1.393 | valid acc 0.380 | mae 1.645 | mse 5.115 | rmse 2.26 | r2 -1.12 | sharp 0.36
saving the model to ./save/2021_300/GRU/checkpoint10.pt
epoch 11 | time used:  0.04s | train_loss 1.480 | valid loss 1.415 | valid acc 0.380 | mae 1.645 | mse 5.115 | rmse 2.26 | r2 -1.12 | sharp 0.36
epoch 12 | time used:  0.06s | train_loss 1.458 | valid loss 1.392 | valid acc 0.380 | mae 1.645 | mse 5.115 | rmse 2.26 | r2 -1.12 | sharp 0.36
epoch 13 | time used:  0.05s | train_loss 1.466 | valid loss 1.392 | valid acc 0.380 | mae 1.645 | mse 5.115 | rmse 2.26 | r2 -1.12 | sharp 0.36
epoch 14 | time used:  0.06s | train_loss 1.474 | valid loss 1.622 | valid acc 0.205 | mae 2.355 | mse 7.955 | rmse 2.82 | r2 -2.30 | sharp 0.00
epoch 15 | time used:  0.06s | train_loss 1.499 | valid loss 1.622 | valid acc 0.205 | mae 2.355 | mse 7.955 | rmse 2.82 | r2 -2.30 | sharp 0.00
epoch 16 | time used:  0.04s | train_loss 1.467 | valid loss 1.622 | valid acc 0.205 | mae 2.355 | mse 7.955 | rmse 2.82 | r2 -2.30 | sharp 0.00
epoch 17 | time used:  0.04s | train_loss 1.475 | valid loss 1.621 | valid acc 0.205 | mae 2.355 | mse 7.955 | rmse 2.82 | r2 -2.30 | sharp 0.00
epoch 18 | time used:  0.06s | train_loss 1.446 | valid loss 1.392 | valid acc 0.380 | mae 1.645 | mse 5.115 | rmse 2.26 | r2 -1.12 | sharp 0.36
epoch 19 | time used:  0.04s | train_loss 1.497 | valid loss 1.392 | valid acc 0.380 | mae 1.645 | mse 5.115 | rmse 2.26 | r2 -1.12 | sharp 0.36
epoch 20 | time used:  0.04s | train_loss 1.470 | valid loss 1.392 | valid acc 0.380 | mae 1.645 | mse 5.115 | rmse 2.26 | r2 -1.12 | sharp 0.36
saving the model to ./save/2021_300/GRU/checkpoint20.pt
epoch 21 | time used:  0.04s | train_loss 1.482 | valid loss 1.393 | valid acc 0.380 | mae 1.645 | mse 5.115 | rmse 2.26 | r2 -1.12 | sharp 0.36
epoch 22 | time used:  0.04s | train_loss 1.468 | valid loss 1.393 | valid acc 0.380 | mae 1.645 | mse 5.115 | rmse 2.26 | r2 -1.12 | sharp 0.36
epoch 23 | time used:  0.04s | train_loss 1.485 | valid loss 1.622 | valid acc 0.205 | mae 2.355 | mse 7.955 | rmse 2.82 | r2 -2.30 | sharp 0.00
epoch 24 | time used:  0.04s | train_loss 1.494 | valid loss 1.392 | valid acc 0.380 | mae 1.645 | mse 5.115 | rmse 2.26 | r2 -1.12 | sharp 0.36
epoch 25 | time used:  0.04s | train_loss 1.487 | valid loss 1.392 | valid acc 0.380 | mae 1.645 | mse 5.115 | rmse 2.26 | r2 -1.12 | sharp 0.36
epoch 26 | time used:  0.04s | train_loss 1.506 | valid loss 1.392 | valid acc 0.380 | mae 1.645 | mse 5.115 | rmse 2.26 | r2 -1.12 | sharp 0.36
epoch 27 | time used:  0.05s | train_loss 1.492 | valid loss 1.394 | valid acc 0.380 | mae 1.645 | mse 5.115 | rmse 2.26 | r2 -1.12 | sharp 0.36
epoch 28 | time used:  0.04s | train_loss 1.465 | valid loss 1.622 | valid acc 0.205 | mae 2.355 | mse 7.955 | rmse 2.82 | r2 -2.30 | sharp 0.00
epoch 29 | time used:  0.04s | train_loss 1.467 | valid loss 1.392 | valid acc 0.380 | mae 1.645 | mse 5.115 | rmse 2.26 | r2 -1.12 | sharp 0.36
epoch 30 | time used:  0.04s | train_loss 1.480 | valid loss 1.393 | valid acc 0.380 | mae 1.645 | mse 5.115 | rmse 2.26 | r2 -1.12 | sharp 0.36
saving the model to ./save/2021_300/GRU/checkpoint30.pt
epoch 31 | time used:  0.05s | train_loss 1.437 | valid loss 1.393 | valid acc 0.380 | mae 1.645 | mse 5.115 | rmse 2.26 | r2 -1.12 | sharp 0.36
epoch 32 | time used:  0.05s | train_loss 1.452 | valid loss 1.393 | valid acc 0.380 | mae 1.645 | mse 5.115 | rmse 2.26 | r2 -1.12 | sharp 0.36
epoch 33 | time used:  0.05s | train_loss 1.479 | valid loss 1.399 | valid acc 0.380 | mae 1.645 | mse 5.115 | rmse 2.26 | r2 -1.12 | sharp 0.36
epoch 34 | time used:  0.04s | train_loss 1.442 | valid loss 1.622 | valid acc 0.205 | mae 2.355 | mse 7.955 | rmse 2.82 | r2 -2.30 | sharp 0.00
epoch 35 | time used:  0.04s | train_loss 1.466 | valid loss 1.622 | valid acc 0.205 | mae 2.355 | mse 7.955 | rmse 2.82 | r2 -2.30 | sharp 0.00
epoch 36 | time used:  0.04s | train_loss 1.466 | valid loss 1.622 | valid acc 0.205 | mae 2.355 | mse 7.955 | rmse 2.82 | r2 -2.30 | sharp 0.00
epoch 37 | time used:  0.04s | train_loss 1.479 | valid loss 1.622 | valid acc 0.205 | mae 2.355 | mse 7.955 | rmse 2.82 | r2 -2.30 | sharp 0.00
epoch 38 | time used:  0.05s | train_loss 1.493 | valid loss 1.566 | valid acc 0.205 | mae 2.355 | mse 7.955 | rmse 2.82 | r2 -2.30 | sharp 0.00
epoch 39 | time used:  0.05s | train_loss 1.489 | valid loss 1.392 | valid acc 0.380 | mae 1.645 | mse 5.115 | rmse 2.26 | r2 -1.12 | sharp 0.36
epoch 40 | time used:  0.04s | train_loss 1.489 | valid loss 1.392 | valid acc 0.380 | mae 1.645 | mse 5.115 | rmse 2.26 | r2 -1.12 | sharp 0.36
saving the model to ./save/2021_300/GRU/checkpoint40.pt
